Exception in Tkinter callback
Traceback (most recent call last):
  File "C:\Python\lib\tkinter\__init__.py", line 1885, in __call__
    return self.func(*args)
  File "D:\Kien\Python\MIS_MONITOR\MIS_MONITOR\main.py", line 11, in show_datamart_screen
    datamart = DatamartScreen(root, login.show_home_screen)
  File "D:\Kien\Python\MIS_MONITOR\MIS_MONITOR\datamart_screen.py", line 148, in __init__
    self.update_datamart_tab()
  File "D:\Kien\Python\MIS_MONITOR\MIS_MONITOR\datamart_screen.py", line 182, in update_datamart_tab
    self.datamart_tree.item(item, tags=(tag_name,))
  File "C:\Python\lib\tkinter\ttk.py", line 1383, in item
    return _val_or_dict(self.tk, kw, self._w, "item", item)
  File "C:\Python\lib\tkinter\ttk.py", line 297, in _val_or_dict
    res = tk.call(*(args + options))
_tkinter.TclError: wrong # args: should be ".!toplevel2.!notebook.!frame.!treeview item item ?option ?value??..."
